Workbook

Sheet groupe
A1: ETU003263 | B1: Anjaramandresiarisoa Fiononana Mitia
A2: ETU003343 | B2: RANDRIANANTENAINA Sedera Valisoa
A3: ETU003356 | B3: RASOLOFOSON Benjanirina Kiady
A4: ETU003365 | B4: RAVOMANANA Sylvio Andriakoto

Sheet liste des taches
A1: Ligne | B1: Catégorie | C1: Module | D1: Page | E1: Description desTaches | F1: Type | G1: Qui | H1: Estimation | I1: Temps passé | J1: Reste à faire | K1: Avancement
A2: 1 | B2: Backoffice | C2: Gestion Connection | D2: login manager/index | E2: Login firebase | F2: Metier | G2: ETU003263 | H2: 60 | I2: =detail_avancement!B2 -> 60 | J2: =MAX(0,H2-I2) -> 0 | K2: =I2/(I2+J2) -> 1
A3: 2 | B3: Backoffice | C3: Gestion Connection | D3: login manager/index | E3: Login Postgres | F3: Metier | G3: ETU003263 | H3: 30 | I3: =detail_avancement!B3 -> 30 | J3: =MAX(0,H3-I3) -> 0 | K3: =I3/(I3+J3) -> 1
A4: 3 | B4: Backoffice | C4: Gestion Connection | D4: login manager/index | E4: Authentification | F4: Integration | G4: ETU003263 | H4: 20 | I4: =detail_avancement!B4 -> 20 | J4: =MAX(0,H4-I4) -> 0 | K4: =I4/(I4+J4) -> 1
A5: 4 | B5: Backoffice | C5: Gestion Connection | D5: login manager/index | E5: formulaire de login | F5: Affichage | G5: ETU003365 | H5: 30 | I5: =detail_avancement!B5 -> 30 | J5: =MAX(0,H5-I5) -> 0 | K5: =I5/(I5+J5) -> 1
A6: 5 | B6: Frontoffice | C6: Gestion Connection | D6: login utilisateur/index | E6: Login firebase | F6: Metier | G6: ETU003343 | H6: 30 | I6: =detail_avancement!B6 -> 30 | J6: =MAX(0,H6-I6) -> 0 | K6: =I6/(I6+J6) -> 1
A7: 6 | B7: Frontoffice | C7: Gestion Connection | D7: login utilisateur/index | E7: Authentification | F7: Integration | G7: ETU003263 | H7: 30 | I7: =detail_avancement!B7 -> 30 | J7: =MAX(0,H7-I7) -> 0 | K7: =I7/(I7+J7) -> 1
A8: 7 | B8: Frontoffice | C8: Gestion Connection | D8: login utilisateur/index | E8: vue +css | F8: Affichage | G8: ETU003343 | H8: 45 | I8: =detail_avancement!B8 -> 45 | J8: =MAX(0,H8-I8) -> 0 | K8: =I8/(I8+J8) -> 1
A9: 8 | B9: Backoffice | C9: Gestion Parametre Blocage | D9: Parametre | E9: get | F9: Metier | G9: ETU003263 | H9: 30 | I9: =detail_avancement!B9 -> 30 | J9: =MAX(0,H9-I9) -> 0 | K9: =I9/(I9+J9) -> 1
A10: 9 | B10: Backoffice | C10: Gestion Parametre Blocage | D10: Parametre | E10: Global | F10: Integration | G10: ETU003263 | H10: 30 | I10: =detail_avancement!B10 -> 30 | J10: =MAX(0,H10-I10) -> 0 | K10: =I10/(I10+J10) -> 1
A11: 10 | B11: Backoffice | C11: Gestion Parametre Blocage | D11: Parametre | E11: Global | F11: Affichage | G11: ETU003365 | H11: 30 | I11: =detail_avancement!B11 -> 30 | J11: =MAX(0,H11-I11) -> 0 | K11: =I11/(I11+J11) -> 1
A12: 11 | B12: Backoffice | C12: Gestion Utilisateur | D12: liste des utilisateurs | E12: List | F12: Metier | G12: ETU003356 | H12: 35 | I12: =detail_avancement!B12 -> 35 | J12: =MAX(0,H12-I12) -> 0 | K12: =I12/(I12+J12) -> 1
A13: 12 | B13: Backoffice | C13: Gestion Utilisateur | D13: liste des utilisateurs | E13: List | F13: Integration | G13: ETU003356 | H13: 30 | I13: =detail_avancement!B13 -> 30 | J13: =MAX(0,H13-I13) -> 0 | K13: =I13/(I13+J13) -> 1
... A49: 48 | B49: Backoffice | C49: Gestion Synchronisation | D49: global | E49: Envoie | F49: Integration | G49: ETU003356 | H49: 30 | I49: =detail_avancement!B49 -> 60 | J49: =MAX(0,H49-I49) -> 0 | K49: =I49/(I49+J49) -> 1
A50: 49 | B50: Docker | C50: Gestion de contenaire docker | E50: creation docker-compose | G50: ETU003356 | H50: 30 | I50: =detail_avancement!B50 -> 30 | J50: =MAX(0,H50-I50) -> 0 | K50: =I50/(I50+J50) -> 1
A51: 50 | B51: Docker | C51: Gestion de contenaire docker | E51: creation dockerfile | G51: ETU003356 | H51: 30 | I51: =detail_avancement!B51 -> 30 | J51: =MAX(0,H51-I51) -> 0 | K51: =I51/(I51+J51) -> 1
A52: 51 | B52: Docker | C52: Gestion de contenaire docker | E52: Installation image et preparation supplementaire | G52: ETU003356 | H52: 30 | I52: =detail_avancement!B52 -> 30 | J52: =MAX(0,H52-I52) -> 0 | K52: =I52/(I52+J52) -> 1
A53: 52 | B53: Frontoffice | C53: Gestion Tableau Recapitulatif | D53: page de recapitulation | E53: getRecapSignalement | F53: Metier | G53: ETU003343 | H53: 60 | I53: =detail_avancement!B53 -> 60 | J53: =MAX(0,H53-I53) -> 0 | K53: =I53/(I53+J53) -> 1
A54: 53 | B54: Frontoffice | C54: Gestion Tableau Recapitulatif | D54: page de recapitulation | E54: Global | F54: Integration | G54: ETU003365 | H54: 60 | I54: =detail_avancement!B54 -> 60 | J54: =MAX(0,H54-I54) -> 0 | K54: =I54/(I54+J54) -> 1
A55: 54 | B55: Frontoffice | C55: Gestion Tableau Recupitulatif | D55: page de recapitulation | E55: vue +css | F55: Affichage | G55: ETU003343 | H55: 60 | I55: =detail_avancement!B55 -> 60 | J55: =MAX(0,H55-I55) -> 0 | K55: =I55/(I55+J55) -> 1
A56: 55 | B56: Backoffice | C56: Gestion Synchronisation | D56: global | E56: Global | F56: Affichage | G56: ETU003343 | H56: 30 | I56: =detail_avancement!B56 -> 30 | J56: =MAX(0,H56-I56) -> 0 | K56: =I56/(I56+J56) -> 1
A57: 56 | B57: Backoffice | C57: Gestion Synchronisation | D57: global | E57: Recuperation | F57: Integration | G57: ETU003343 | H57: 60 | I57: =detail_avancement!B57 -> 60 | J57: =MAX(0,H57-I57) -> 0 | K57: =I57/(I57+J57) -> 1
A58: 57 | B58: Backoffice | C58: Gestion Signalement Status | D58: fiche de signalement | E58: Modification | F58: Affichage | G58: ETU003343 | H58: 20 | I58: =detail_avancement!B58 -> 60 | J58: =MAX(0,H58-I58) -> 0 | K58: =I58/(I58+J58) -> 1
A59: 58 | B59: Backoffice | C59: Gestion Signalement Status | D59: fiche de signalement | E59: Modification | F59: Integration | G59: ETU003263 | H59: 30 | I59: =detail_avancement!B59 -> 60 | J59: =MAX(0,H59-I59) -> 0 | K59: =I59/(I59+J59) -> 1
A60: 59 | B60: Backoffice | C60: Gestion Signalement Status | D60: fiche de signalement | E60: Modification | F60: Metier | G60: ETU003263 | H60: 40 | I60: =detail_avancement!B60 -> 60 | J60: =MAX(0,H60-I60) -> 0 | K60: =I60/(I60+J60) -> 1
A61: 60 | B61: Backoffice | C61: Gestion des sessions et authentification | D61: protectedRoute | E61: global | F61: Metier | G61: ETU003343 | H61: 30 | I61: =detail_avancement!B61 -> 60 | J61: =MAX(0,H61-I61) -> 0 | K61: =I61/(I61+J61) -> 1
A62: 61 | B62: Backoffice | C62: Gestion sychronsation | D62: parametre | E62: getAllNoSyncPostgres | F62: Metier | G62: ETU003356 | H62: 30 | I62: =detail_avancement!B62 -> 60 | J62: =MAX(0,H62-I62) -> 0 | K62: =I62/(I62+J62) -> 1
A63: 62 | B63: Backoffice | C63: Gestion sychronsation | D63: parametre | E63: getAllNoSyncFirebase | F63: Metier | G63: ETU003343 | H63: 30 | I63: =detail_avancement!B63 -> 60 | J63: =MAX(0,H63-I63) -> 0 | K63: =I63/(I63+J63) -> 1
A64: 63 | B64: Backoffice | C64: Gestion signalement | D64: asigner signalement | E64: fenetre dans le fiche signalement | F64: affichage | G64: ETU003365 | H64: 40 | I64: =detail_avancement!B64 -> 40 | J64: =MAX(0,H64-I64) -> 0 | K64: =I64/(I64+J64) -> 1
... A77: 76 | B77: Backoffice | C77: Gestion Signalement | D77: Fiche de signalement | E77: AddImageSignalement | F77: Metier | G77: ETU003263 | H77: 30 | I77: =detail_avancement!B77 -> 60 | J77: =MAX(0,H77-I77) -> 0 | K77: =I77/(I77+J77) -> 1
A78: 77 | B78: Backoffice | C78: Documentation technique | F78: global | G78: ETU003356 | H78: 60 | I78: =detail_avancement!B78 -> 60 | J78: =MAX(0,H78-I78) -> 0 | K78: =I78/(I78+J78) -> 1
A79: 78 | B79: Backoffice | C79: Gestion Signalement | D79: Fiche de signalemnt | E79: appel api | F79: integration | G79: ETU003356 | H79: 60 | I79: =detail_avancement!B79 -> 60 | J79: =MAX(0,H79-I79) -> 0 | K79: =I79/(I79+J79) -> 1
A80: 79 | B80: Backoffice | C80: Documentation technique | D80: Fiche de signalemnt | E80: vue+css | F80: affichage | G80: ETU003263 | H80: 30 | I80: =detail_avancement!B80 -> 30 | J80: =MAX(0,H80-I80) -> 0 | K80: =I80/(I80+J80) -> 1
A81: 80 | B81: Backoffice | C81: Gestion Notification | D81: global | E81: EnvoyeNotif | F81: metier | G81: ETU003365 | H81: 30 | I81: =detail_avancement!B81 -> 40 | J81: =MAX(0,H81-I81) -> 0 | K81: =I81/(I81+J81) -> 1
A82: 81 | B82: Backoffice | C82: Gestion Notification | D82: global | E82: EnregistrementNotifFirebase | F82: metier | G82: ETU003343 | H82: 30 | I82: =detail_avancement!B82 -> 45 | J82: =MAX(0,H82-I82) -> 0 | K82: =I82/(I82+J82) -> 1
A83: 82 | B83: Frontoffice | C83: Gestion Notification | D83: list notification | E83: getNotif | F83: metier | G83: ETU003365 | H83: 30 | I83: =detail_avancement!B83 -> 40 | J83: =MAX(0,H83-I83) -> 0 | K83: =I83/(I83+J83) -> 1
A84: 83 | B84: Frontoffice | C84: Gestion Notification | D84: list notification | E84: global | F84: integration | G84: ETU003365 | H84: 40 | I84: =detail_avancement!B84 -> 40 | J84: =MAX(0,H84-I84) -> 0 | K84: =I84/(I84+J84) -> 1
A85: 84 | B85: Frontoffice | C85: Gestion Notification | D85: list notification | E85: vue+css | F85: affichage | G85: ETU003263 | H85: 30 | I85: =detail_avancement!B85 -> 40 | J85: =MAX(0,H85-I85) -> 0 | K85: =I85/(I85+J85) -> 1
A86: 85 | B86: Frontoffice | C86: Refactor css visiteur | D86: global | E86: vue+css | F86: affichage | G86: ETU003356 | H86: 30 | I86: =detail_avancement!B86 -> 30 | J86: =MAX(0,H86-I86) -> 0 | K86: =I86/(I86+J86) -> 1
A87: 86 | B87: Frontoffice | C87: Refactor css utilisateur (mobile) | D87: global | E87: vue+css | F87: affichage | G87: ETU003356 | H87: 60 | I87: =detail_avancement!B87 -> 60 | J87: =MAX(0,H87-I87) -> 0 | K87: =I87/(I87+J87) -> 1
...

Sheet Recap
A9: Avancement | B9: =avancement!D2 -> 1

Sheet detail_avancement
A1: Ligne | B1: Total | C1: 46048 | D1: 46049 | E1: 46050 | F1: 46051 | G1: 46052 | H1: 46053 | I1: 46054 | J1: 46055 | K1: 46056 | L1: 46057 | M1: 46058 | N1: 46059 | O1: 46060 | P1: 46061 | Q1: 46062 | R1: 46063
A2: 1 | B2: =SUM(C2:R2) -> 60 | C2: 60 | D2: 0
A3: 2 | B3: =SUM(C3:R3) -> 30 | C3: 30
A4: 3 | B4: =SUM(C4:R4) -> 20 | C4: 20
A5: 4 | B5: =SUM(C5:R5) -> 30 | C5: 30
A6: 5 | B6: =SUM(C6:R6) -> 30 | C6: 30
A7: 6 | B7: =SUM(C7:R7) -> 30 | C7: 30
A8: 7 | B8: =SUM(C8:R8) -> 45 | C8: 45
A9: 8 | B9: =SUM(C9:R9) -> 30 | C9: 30
A10: 9 | B10: =SUM(C10:R10) -> 30 | C10: 30
A11: 10 | B11: =SUM(C11:R11) -> 30 | C11: 30
A12: 11 | B12: =SUM(C12:R12) -> 35 | C12: 35
A13: 12 | B13: =SUM(C13:R13) -> 30 | C13: 30
A14: 13 | B14: =SUM(C14:R14) -> 20 | C14: 20
A15: 14 | B15: =SUM(C15:R15) -> 30 | G15: 30
A16: 15 | B16: =SUM(C16:R16) -> 30 | G16: 30
A17: 16 | B17: =SUM(C17:R17) -> 20 | G17: 20
A18: 17 | B18: =SUM(C18:R18) -> 20 | D18: 20
A19: 18 | B19: =SUM(C19:R19) -> 20 | D19: 20
A20: 19 | B20: =SUM(C20:R20) -> 30 | G20: 30
A21: 20 | B21: =SUM(C21:R21) -> 30 | C21: 30
A22: 21 | B22: =SUM(C22:R22) -> 10 | C22: 10
A23: 22 | B23: =SUM(C23:R23) -> 30 | C23: 20 | D23: 10
A24: 23 | B24: =SUM(C24:R24) -> 30 | C24: 30
A25: 24 | B25: =SUM(C25:R25) -> 25 | G25: 25
A26: 25 | B26: =SUM(C26:R26) -> 40 | J26: 40
A27: 26 | B27: =SUM(C27:R27) -> 20 | G27: 20
A28: 27 | B28: =SUM(C28:R28) -> 20 | G28: 20
A29: 28 | B29: =SUM(C29:R29) -> 40 | J29: 40
A30: 29 | B30: =SUM(C30:R30) -> 20 | J30: 20
A31: 30 | B31: =SUM(C31:R31) -> 60 | J31: 60
A32: 31 | B32: =SUM(C32:R32) -> 20 | J32: 20
A33: 32 | B33: =SUM(C33:R33) -> 40 | J33: 40
A34: 33 | B34: =SUM(C34:R34) -> 45 | J34: 45
A35: 34 | B35: =SUM(C35:R35) -> 30 | J35: 30
A36: 35 | B36: =SUM(C36:R36) -> 20 | J36: 20
A37: 36 | B37: =SUM(C37:R37) -> 20 | J37: 20
A38: 37 | B38: =SUM(C38:R38) -> 20 | D38: 20
A39: 38 | B39: =SUM(C39:R39) -> 40 | J39: 40
A40: 39 | B40: =SUM(C40:R40) -> 30 | J40: 30
...

Sheet avancement
A1: estimation total | B1: temps passé total | C1: reste à faire total | D1: avancement | E1: dépassement | F1: Echelle
A2: =SUM('liste des taches'!H:H) -> 3195 | B2: =SUM('liste des taches'!I:I) -> 3775 | C2: =SUM('liste des taches'!J:J) -> 0 | D2: =(B2/(B2+C2)) -> 1 | E2: =((B2+C2)-A2)/A2 -> 0.18153365 | F2: =ROUNDDOWN(D2*10,0) -> 10
C3: =C2/60 -> 0 | D3: heure
